from db_connect import DbConnect

class UsuarioModel:

    def __init__(self):
        self.conn = DbConnect().connect()

        if self.conn is None:
            raise ConnectionError("No se pudo establecer la conexi√≥n a la base de datos.")

        self.cursor = self.conn.cursor(dictionary=True)


    def get_usuario(self, id):
        sql = "SELECT * FROM usuarios WHERE id_usuario = %s"
        self.cursor.execute(sql, (id))

        row = self.cursor.fetchone()
        return row
 

    def get_all_usuarios(self):
        sql = "SELECT * FROM usuarios"
        self.cursor.execute(sql)

        all_usuarios = self.cursor.fetchall()
        return all_usuarios

    def create_usuario(self, datos):
        sql = "INSERT INTO usuarios (id_usuario, nombre, apellido, fecha_nacimiento, email, telefono, profesion, statu) " \
        "VALUES (%s, %s, %s, %s, %s, %s, %s, %s)"
      
        try: 
            self.cursor.execute(sql, tuple(datos))
            self.conn.commit()
            return self.cursor.lastrowid

        except Exception as e:
            self.conn.rollback()
            print(f"Error inesperado: {e}")
            return None

    def update_usuario(self, datos):
        sql = "UPDATE usuarios SET nombre = %s, email = %s WHERE id_usuario = %s"
        
        try: 
            self.cursor.execute(sql, tuple(datos))
            self.conn.commit()
            return self.cursor.rowcount

        except Exception as e:
            self.conn.rollback()
            print(f"Error inesperado: {e}")
            return None

    def delete_usuario(self, id):
        sql = "DELETE FROM usuarios WHERE id_usuario = %s"
        try: 
            self.cursor.execute(sql, (id))
            self.conn.commit()
            return self.cursor.rowcount

        except Exception as e:
            self.conn.rollback()
            print(f"Error inesperado: {e}")
            return None
